Workbook

Sheet Cover
B2: Progress Technologies
B3: Risk-Driven Statement of Applicability - ISO/IEC 27001:2022 (Working Workbook)
B5: Document ID | C5: PT-ISMS-SOA-001
B6: Version / status | C6: 1.0 - Draft for management approval
B7: Date | C7: 46321
B8: Author | C8: Devavrat Yadav
B9: Original author | C9: Taimuri Jlal - original project brief, scenario and SoA template (Project 02)
B10: Classification | C10: Confidential
B11: Next review | C11: 46503
B12: Companion document | C12: Word report: Progress Technologies - Risk-Driven Statement of Applicability (sections 1-22)
B15: Sheets
B16: Summary | C16: Control counts by theme and status (live formulas from the SoA sheet)
B17: SoA | C17: All 93 Annex A controls: applicability, status, justification, evidence, linked risks, validation flag
B18: Exclusions | C18: 10 excluded controls with reason, alternative measure and re-evaluation trigger
B19: Risk Register | C19: R-001 to R-013 with inherent and target residual ratings
B20: Traceability | C20: Control-by-risk grid with live coverage counts
B21: Evidence Index | C21: EV-01 to EV-50 with owner, system of record, cadence and live count of controls citing each
B22: Actions | C22: Priority remediation plan A-01 to A-20
B23: Additional Controls | C23: Controls beyond Annex A (clause 6.1.3 b)
B25: Important
B26: Statuses, owners and evidence artefacts are the author's assessed baseline derived from the scenario. They are not confirmed records.
B27: Never keep a control as Implemented unless its evidence can be produced on demand. Use the 'Evidence validated' column on the SoA sheet; any Implemented control not marked Yes is flagged.
B28: Yellow cells on the SoA sheet (owner, evidence validated) are for Progress Technologies to complete.
B29: Applicable, Status and Evidence validated are drop-down lists; Summary and Traceability counts recalculate when they change.

Sheet Summary
A1: Statement of Applicability Summary
A2: Live counts from the SoA sheet. Baseline at 26 October 2026.
A4: Theme | B4: Total | C4: Applicable | D4: Excluded | E4: Implemented | F4: Partial | G4: Planned
A5: 5. Organizational | B5: =COUNTIFS(SoA!$A$2:$A$94,$A5) -> 37 | C5: =COUNTIFS(SoA!$A$2:$A$94,$A5,SoA!$D$2:$D$94,"Yes") -> 37 | D5: =COUNTIFS(SoA!$A$2:$A$94,$A5,SoA!$D$2:$D$94,"No") -> 0 | E5: =COUNTIFS(SoA!$A$2:$A$94,$A5,SoA!$E$2:$E$94,"Implemented") -> 11 | F5: =COUNTIFS(SoA!$A$2:$A$94,$A5,SoA!$E$2:$E$94,"Partial") -> 23 | G5: =COUNTIFS(SoA!$A$2:$A$94,$A5,SoA!$E$2:$E$94,"Planned") -> 3
A6: 6. People | B6: =COUNTIFS(SoA!$A$2:$A$94,$A6) -> 8 | C6: =COUNTIFS(SoA!$A$2:$A$94,$A6,SoA!$D$2:$D$94,"Yes") -> 8 | D6: =COUNTIFS(SoA!$A$2:$A$94,$A6,SoA!$D$2:$D$94,"No") -> 0 | E6: =COUNTIFS(SoA!$A$2:$A$94,$A6,SoA!$E$2:$E$94,"Implemented") -> 6 | F6: =COUNTIFS(SoA!$A$2:$A$94,$A6,SoA!$E$2:$E$94,"Partial") -> 2 | G6: =COUNTIFS(SoA!$A$2:$A$94,$A6,SoA!$E$2:$E$94,"Planned") -> 0
A7: 7. Physical | B7: =COUNTIFS(SoA!$A$2:$A$94,$A7) -> 14 | C7: =COUNTIFS(SoA!$A$2:$A$94,$A7,SoA!$D$2:$D$94,"Yes") -> 5 | D7: =COUNTIFS(SoA!$A$2:$A$94,$A7,SoA!$D$2:$D$94,"No") -> 9 | E7: =COUNTIFS(SoA!$A$2:$A$94,$A7,SoA!$E$2:$E$94,"Implemented") -> 1 | F7: =COUNTIFS(SoA!$A$2:$A$94,$A7,SoA!$E$2:$E$94,"Partial") -> 4 | G7: =COUNTIFS(SoA!$A$2:$A$94,$A7,SoA!$E$2:$E$94,"Planned") -> 0
A8: 8. Technological | B8: =COUNTIFS(SoA!$A$2:$A$94,$A8) -> 34 | C8: =COUNTIFS(SoA!$A$2:$A$94,$A8,SoA!$D$2:$D$94,"Yes") -> 33 | D8: =COUNTIFS(SoA!$A$2:$A$94,$A8,SoA!$D$2:$D$94,"No") -> 1 | E8: =COUNTIFS(SoA!$A$2:$A$94,$A8,SoA!$E$2:$E$94,"Implemented") -> 15 | F8: =COUNTIFS(SoA!$A$2:$A$94,$A8,SoA!$E$2:$E$94,"Partial") -> 13 | G8: =COUNTIFS(SoA!$A$2:$A$94,$A8,SoA!$E$2:$E$94,"Planned") -> 5
A9: TOTAL | B9: =SUM(B5:B8) -> 93 | C9: =SUM(C5:C8) -> 83 | D9: =SUM(D5:D8) -> 10 | E9: =SUM(E5:E8) -> 33 | F9: =SUM(F5:F8) -> 42 | G9: =SUM(G5:G8) -> 8
A11: Integrity checks
A12: Total controls = 93 | B12: =IF(B9=93,"OK","CHECK") -> OK
A13: Applicable + excluded = total | B13: =IF(C9+D9=B9,"OK","CHECK") -> OK
A14: Implemented + partial + planned = applicable | B14: =IF(E9+F9+G9=C9,"OK","CHECK") -> OK
A15: Implemented controls with evidence not yet validated | B15: =COUNTIF(SoA!$M$2:$M$94,"Validate evidence") -> 33
A16: Rows with status conflict | B16: =COUNTIF(SoA!$M$2:$M$94,"Status conflict") -> 0
A18: Share of applicable controls
A19: Implemented | B19: =IF($C$9=0,0,E9/$C$9) -> 0.39759036
A20: Partial | B20: =IF($C$9=0,0,F9/$C$9) -> 0.5060241
A21: Planned | B21: =IF($C$9=0,0,G9/$C$9) -> 0.096385542
A23: Note: Implemented status is a baseline assumption pending the evidence walk-through (see Cover sheet).

Sheet SoA
A1: Theme | B1: Ref | C1: Control | D1: Applicable | E1: Status | F1: Justification (risk link) | G1: Evidence Ref | H1: Linked risks | I1: Exclusion ref | J1: Remediation action | K1: Control owner | L1: Evidence validated | M1: Check
A2: 5. Organizational | B2: 5.1 | C2: Policies for information security | D2: Yes | E2: Implemented | F2: Governance anchor of the ISMS (clause 5.2); direction for treating R-001 and R-003; customer contracts require a documented policy set. | G2: EV-01 | H2: R-001, R-003 | L2: Pending | M2: =IF(AND(E2="Implemented",L2<>"Yes"),"Validate evidence",IF(AND(D2="Yes",E2="N/A"),"Status conflict",IF(AND(D2="No",E2<>"N/A"),"Status conflict","OK"))) -> Validate evidence
A3: 5. Organizational | B3: 5.2 | C3: Information security roles and responsibilities | D3: Yes | E3: Implemented | F3: Names accountable owners for ISMS, risk and cloud security in a fully remote organisation (R-001, R-003, R-004). | G3: EV-03 | H3: R-003, R-004 | L3: Pending | M3: =IF(AND(E3="Implemented",L3<>"Yes"),"Validate evidence",IF(AND(D3="Yes",E3="N/A"),"Status conflict",IF(AND(D3="No",E3<>"N/A"),"Status conflict","OK"))) -> Validate evidence
A4: 5. Organizational | B4: 5.3 | C4: Segregation of duties | D4: Yes | E4: Partial | F4: Limits single-person misuse of production and admin rights (R-001, R-003, R-004). Peer-approved deployments operate; break-glass and small-team admin overlap need compensating review. | G4: EV-11, EV-27 | H4: R-001, R-003, R-004 | L4: n/a | M4: =IF(AND(E4="Implemented",L4<>"Yes"),"Validate evidence",IF(AND(D4="Yes",E4="N/A"),"Status conflict",IF(AND(D4="No",E4<>"N/A"),"Status conflict","OK"))) -> OK
A5: 5. Organizational | B5: 5.4 | C5: Management responsibilities | D5: Yes | E5: Implemented | F5: Management directs and enforces compliance across a remote workforce (R-004, R-007). | G5: EV-03, EV-04 | H5: R-004, R-007 | L5: Pending | M5: =IF(AND(E5="Implemented",L5<>"Yes"),"Validate evidence",IF(AND(D5="Yes",E5="N/A"),"Status conflict",IF(AND(D5="No",E5<>"N/A"),"Status conflict","OK"))) -> Validate evidence
A6: 5. Organizational | B6: 5.5 | C6: Contact with authorities | D6: Yes | E6: Partial | F6: Needed for GDPR breach notification and incident escalation (R-001, R-011). Contact list exists; escalation paths untested. | G6: EV-35 | H6: R-011 | L6: n/a | M6: =IF(AND(E6="Implemented",L6<>"Yes"),"Validate evidence",IF(AND(D6="Yes",E6="N/A"),"Status conflict",IF(AND(D6="No",E6<>"N/A"),"Status conflict","OK"))) -> OK
A7: 5. Organizational | B7: 5.6 | C7: Contact with special interest groups | D7: Yes | E7: Partial | F7: Low-cost source of cloud-threat and vulnerability bulletins (R-003, R-007). Memberships to be formalised. | G7: EV-35 | H7: R-007 | L7: n/a | M7: =IF(AND(E7="Implemented",L7<>"Yes"),"Validate evidence",IF(AND(D7="Yes",E7="N/A"),"Status conflict",IF(AND(D7="No",E7<>"N/A"),"Status conflict","OK"))) -> OK
A8: 5. Organizational | B8: 5.7 | C8: Threat intelligence | D8: Yes | E8: Partial | F8: Feeds R-003, R-007 and R-009 from AWS and vendor advisories. Triage SLA and reporting not yet formal. | G8: EV-34 | H8: R-003, R-007, R-009 | L8: n/a | M8: =IF(AND(E8="Implemented",L8<>"Yes"),"Validate evidence",IF(AND(D8="Yes",E8="N/A"),"Status conflict",IF(AND(D8="No",E8<>"N/A"),"Status conflict","OK"))) -> OK
A9: 5. Organizational | B9: 5.8 | C9: Information security in project management | D9: Yes | E9: Partial | F9: Security gate for new features and infrastructure changes (R-003, R-013). Gate not yet mandatory for every project type. | G9: EV-40 | H9: R-003, R-013 | L9: n/a | M9: =IF(AND(E9="Implemented",L9<>"Yes"),"Validate evidence",IF(AND(D9="Yes",E9="N/A"),"Status conflict",IF(AND(D9="No",E9<>"N/A"),"Status conflict","OK"))) -> OK
A10: 5. Organizational | B10: 5.9 | C10: Inventory of information and other associated assets | D10: Yes | E10: Partial | F10: Unknown assets cannot be protected (R-001, R-002, R-003). Laptops tracked in MDM and AWS resources in AWS Config; information asset owners incomplete. | G10: EV-07, EV-24 | H10: R-002 | L10: n/a | M10: =IF(AND(E10="Implemented",L10<>"Yes"),"Validate evidence",IF(AND(D10="Yes",E10="N/A"),"Status conflict",IF(AND(D10="No",E10<>"N/A"),"Status conflict","OK"))) -> OK
A11: 5. Organizational | B11: 5.10 | C11: Acceptable use of information and other associated assets | D11: Yes | E11: Implemented | F11: Sets endpoint, SaaS and data-handling behaviour for remote staff (R-002, R-004, R-007); acknowledged at onboarding. | G11: EV-08 | H11: R-002, R-004, R-007 | L11: Pending | M11: =IF(AND(E11="Implemented",L11<>"Yes"),"Validate evidence",IF(AND(D11="Yes",E11="N/A"),"Status conflict",IF(AND(D11="No",E11<>"N/A"),"Status conflict","OK"))) -> Validate evidence
A12: 5. Organizational | B12: 5.11 | C12: Return of assets | D12: Yes | E12: Implemented | F12: Prevents leavers retaining laptops or data (R-002, R-004). Courier return and reconciliation process used for remote leavers. | G12: EV-20, EV-24 | H12: R-002, R-004 | L12: Pending | M12: =IF(AND(E12="Implemented",L12<>"Yes"),"Validate evidence",IF(AND(D12="Yes",E12="N/A"),"Status conflict",IF(AND(D12="No",E12<>"N/A"),"Status conflict","OK"))) -> Validate evidence
A13: 5. Organizational | B13: 5.12 | C13: Classification of information | D13: Yes | E13: Partial | F13: Drives encryption, access and retention for customer data (R-001, R-011, R-012). Scheme approved; tagging of cloud data stores in progress. | G13: EV-09 | H13: R-001, R-011, R-012 | L13: n/a | M13: =IF(AND(E13="Implemented",L13<>"Yes"),"Validate evidence",IF(AND(D13="Yes",E13="N/A"),"Status conflict",IF(AND(D13="No",E13<>"N/A"),"Status conflict","OK"))) -> OK
A14: 5. Organizational | B14: 5.13 | C14: Labelling of information | D14: Yes | E14: Planned | F14: Proportionate labelling only: document footers and cloud resource tags (R-001, R-011). Automated tagging scheduled in Wave 1. | G14: EV-09 | H14: R-011 | J14: A-07 | L14: n/a | M14: =IF(AND(E14="Implemented",L14<>"Yes"),"Validate evidence",IF(AND(D14="Yes",E14="N/A"),"Status conflict",IF(AND(D14="No",E14<>"N/A"),"Status conflict","OK"))) -> OK
A15: 5. Organizational | B15: 5.14 | C15: Information transfer | D15: Yes | E15: Partial | F15: Controls transfer of customer and internal data via TLS, approved sharing tools and NDAs (R-001, R-011). Customer data export rules being finalised. | G15: EV-09, EV-30 | H15: R-001, R-011 | L15: n/a | M15: =IF(AND(E15="Implemented",L15<>"Yes"),"Validate evidence",IF(AND(D15="Yes",E15="N/A"),"Status conflict",IF(AND(D15="No",E15<>"N/A"),"Status conflict","OK"))) -> OK
A16: 5. Organizational | B16: 5.15 | C16: Access control | D16: Yes | E16: Implemented | F16: Least-privilege, role-based access to AWS and SaaS (R-001, R-004). | G16: EV-10, EV-11 | H16: R-001, R-004 | L16: Pending | M16: =IF(AND(E16="Implemented",L16<>"Yes"),"Validate evidence",IF(AND(D16="Yes",E16="N/A"),"Status conflict",IF(AND(D16="No",E16<>"N/A"),"Status conflict","OK"))) -> Validate evidence
A17: 5. Organizational | B17: 5.16 | C17: Identity management | D17: Yes | E17: Implemented | F17: Central identity provider with joiner-mover-leaver lifecycle (R-001, R-004). | G17: EV-11, EV-46 | H17: R-001, R-004 | L17: Pending | M17: =IF(AND(E17="Implemented",L17<>"Yes"),"Validate evidence",IF(AND(D17="Yes",E17="N/A"),"Status conflict",IF(AND(D17="No",E17<>"N/A"),"Status conflict","OK"))) -> Validate evidence
A18: 5. Organizational | B18: 5.17 | C18: Authentication information | D18: Yes | E18: Implemented | F18: Password manager, MFA and secrets manager for machine credentials (R-001, R-007, R-010). | G18: EV-44, EV-46 | H18: R-001, R-007, R-010 | L18: Pending | M18: =IF(AND(E18="Implemented",L18<>"Yes"),"Validate evidence",IF(AND(D18="Yes",E18="N/A"),"Status conflict",IF(AND(D18="No",E18<>"N/A"),"Status conflict","OK"))) -> Validate evidence
A19: 5. Organizational | B19: 5.18 | C19: Access rights | D19: Yes | E19: Partial | F19: Quarterly AWS access reviews operate; extension to all SaaS applications outstanding (R-001, R-004). | G19: EV-11 | H19: R-001, R-004 | J19: A-09 | L19: n/a | M19: =IF(AND(E19="Implemented",L19<>"Yes"),"Validate evidence",IF(AND(D19="Yes",E19="N/A"),"Status conflict",IF(AND(D19="No",E19<>"N/A"),"Status conflict","OK"))) -> OK
A20: 5. Organizational | B20: 5.19 | C20: Information security in supplier relationships | D20: Yes | E20: Partial | F20: AWS and other suppliers hold customer data or underpin the service (R-005, R-009). Supplier tiering in progress. | G20: EV-12 | H20: R-005, R-009 | L20: n/a | M20: =IF(AND(E20="Implemented",L20<>"Yes"),"Validate evidence",IF(AND(D20="Yes",E20="N/A"),"Status conflict",IF(AND(D20="No",E20<>"N/A"),"Status conflict","OK"))) -> OK
A21: 5. Organizational | B21: 5.20 | C21: Addressing information security within supplier agreements | D21: Yes | E21: Partial | F21: Security and data-protection terms with AWS and sub-processors (R-005, R-011). Customer flow-down clauses under review. | G21: EV-13 | H21: R-005, R-011 | L21: n/a | M21: =IF(AND(E21="Implemented",L21<>"Yes"),"Validate evidence",IF(AND(D21="Yes",E21="N/A"),"Status conflict",IF(AND(D21="No",E21<>"N/A"),"Status conflict","OK"))) -> OK
A22: 5. Organizational | B22: 5.21 | C22: Managing information security in the ICT supply chain | D22: Yes | E22: Partial | F22: Open-source dependencies and CI/CD tooling are the main ICT supply chain (R-009). Dependency scanning live; SBOM and formal standard not yet produced. | G22: EV-12, EV-26 | H22: R-005, R-009 | L22: n/a | M22: =IF(AND(E22="Implemented",L22<>"Yes"),"Validate evidence",IF(AND(D22="Yes",E22="N/A"),"Status conflict",IF(AND(D22="No",E22<>"N/A"),"Status conflict","OK"))) -> OK
A23: 5. Organizational | B23: 5.22 | C23: Monitoring, review and change management of supplier services | D23: Yes | E23: Partial | F23: Ongoing assurance over AWS (R-005) and the evidence base for inherited physical controls. Annual review of AWS certificates and reports being scheduled. | G23: EV-12 | H23: R-005 | J23: A-04 | L23: n/a | M23: =IF(AND(E23="Implemented",L23<>"Yes"),"Validate evidence",IF(AND(D23="Yes",E23="N/A"),"Status conflict",IF(AND(D23="No",E23<>"N/A"),"Status conflict","OK"))) -> OK
A24: 5. Organizational | B24: 5.23 | C24: Information security for use of cloud services | D24: Yes | E24: Implemented | F24: Core control for a 100% AWS company: cloud security standard and shared-responsibility matrix define who secures what (R-003, R-005). | G24: EV-14, EV-31 | H24: R-003, R-005 | L24: Pending | M24: =IF(AND(E24="Implemented",L24<>"Yes"),"Validate evidence",IF(AND(D24="Yes",E24="N/A"),"Status conflict",IF(AND(D24="No",E24<>"N/A"),"Status conflict","OK"))) -> Validate evidence
A25: 5. Organizational | B25: 5.24 | C25: Information security incident management planning and preparation | D25: Yes | E25: Implemented | F25: Defined incident roles, severity model and reporting channels (R-001, R-006). | G25: EV-15 | H25: R-006 | L25: Pending | M25: =IF(AND(E25="Implemented",L25<>"Yes"),"Validate evidence",IF(AND(D25="Yes",E25="N/A"),"Status conflict",IF(AND(D25="No",E25<>"N/A"),"Status conflict","OK"))) -> Validate evidence
A26: 5. Organizational | B26: 5.25 | C26: Assessment and decision on information security events | D26: Yes | E26: Partial | F26: Triage criteria defined; evidence of consistent event classification still thin (R-001, R-003). | G26: EV-15, EV-28 | H26: R-003 | L26: n/a | M26: =IF(AND(E26="Implemented",L26<>"Yes"),"Validate evidence",IF(AND(D26="Yes",E26="N/A"),"Status conflict",IF(AND(D26="No",E26<>"N/A"),"Status conflict","OK"))) -> OK
A27: 5. Organizational | B27: 5.26 | C27: Response to information security incidents | D27: Yes | E27: Partial | F27: Playbooks for cloud credential compromise and data exposure; not yet validated by a tabletop exercise (R-001, R-003, R-006, R-008). | G27: EV-15 | H27: R-003, R-006, R-008 | J27: A-15 | L27: n/a | M27: =IF(AND(E27="Implemented",L27<>"Yes"),"Validate evidence",IF(AND(D27="Yes",E27="N/A"),"Status conflict",IF(AND(D27="No",E27<>"N/A"),"Status conflict","OK"))) -> OK
A28: 5. Organizational | B28: 5.27 | C28: Learning from information security incidents | D28: Yes | E28: Partial | F28: Post-incident review template exists; limited operating history to evidence (R-003, R-006). | G28: EV-15 | H28: R-006 | L28: n/a | M28: =IF(AND(E28="Implemented",L28<>"Yes"),"Validate evidence",IF(AND(D28="Yes",E28="N/A"),"Status conflict",IF(AND(D28="No",E28<>"N/A"),"Status conflict","OK"))) -> OK
A29: 5. Organizational | B29: 5.28 | C29: Collection of evidence | D29: Yes | E29: Planned | F29: Forensic readiness (log retention, snapshot and chain-of-custody procedure) needed for customer and regulator enquiries (R-001, R-004). | G29: EV-15, EV-28 | H29: R-004 | J29: A-08 | L29: n/a | M29: =IF(AND(E29="Implemented",L29<>"Yes"),"Validate evidence",IF(AND(D29="Yes",E29="N/A"),"Status conflict",IF(AND(D29="No",E29<>"N/A"),"Status conflict","OK"))) -> OK
A30: 5. Organizational | B30: 5.29 | C30: Information security during disruption | D30: Yes | E30: Partial | F30: Keeps security controls effective during outage and failover (R-005, R-006, R-008). | G30: EV-16 | H30: R-005, R-006, R-008 | L30: n/a | M30: =IF(AND(E30="Implemented",L30<>"Yes"),"Validate evidence",IF(AND(D30="Yes",E30="N/A"),"Status conflict",IF(AND(D30="No",E30<>"N/A"),"Status conflict","OK"))) -> OK
A31: 5. Organizational | B31: 5.30 | C31: ICT readiness for business continuity | D31: Yes | E31: Partial | F31: Multi-AZ design in place; cross-region recovery test pending (R-005, R-006, R-008). | G31: EV-16, EV-29 | H31: R-005, R-006, R-008 | J31: A-18 | L31: n/a | M31: =IF(AND(E31="Implemented",L31<>"Yes"),"Validate evidence",IF(AND(D31="Yes",E31="N/A"),"Status conflict",IF(AND(D31="No",E31<>"N/A"),"Status conflict","OK"))) -> OK
A32: 5. Organizational | B32: 5.31 | C32: Legal, statutory, regulatory and contractual requirements | D32: Yes | E32: Implemented | F32: 200+ enterprise contracts, GDPR processing in eu-west-1 and customer security addenda tracked in a register (R-011). | G32: EV-17 | H32: R-011 | L32: Pending | M32: =IF(AND(E32="Implemented",L32<>"Yes"),"Validate evidence",IF(AND(D32="Yes",E32="N/A"),"Status conflict",IF(AND(D32="No",E32<>"N/A"),"Status conflict","OK"))) -> Validate evidence
A33: 5. Organizational | B33: 5.32 | C33: Intellectual property rights | D33: Yes | E33: Partial | F33: Software and open-source licence compliance for platform code (R-009). Licence register and scanning to be completed. | G33: EV-42 | H33: R-009 | L33: n/a | M33: =IF(AND(E33="Implemented",L33<>"Yes"),"Validate evidence",IF(AND(D33="Yes",E33="N/A"),"Status conflict",IF(AND(D33="No",E33<>"N/A"),"Status conflict","OK"))) -> OK
A34: 5. Organizational | B34: 5.33 | C34: Protection of records | D34: Yes | E34: Partial | F34: Protects audit trails, contracts and security records (R-011, R-012). Retention schedule approved; immutable log storage being rolled out. | G34: EV-41 | H34: R-011, R-012 | L34: n/a | M34: =IF(AND(E34="Implemented",L34<>"Yes"),"Validate evidence",IF(AND(D34="Yes",E34="N/A"),"Status conflict",IF(AND(D34="No",E34<>"N/A"),"Status conflict","OK"))) -> OK
A35: 5. Organizational | B35: 5.34 | C35: Privacy and protection of PII | D35: Yes | E35: Partial | F35: Progress acts as processor of customer personal data (R-011, R-012). RoPA, DPAs and DSAR procedure operate; DPIA coverage incomplete. | G35: EV-18 | H35: R-011, R-012 | L35: n/a | M35: =IF(AND(E35="Implemented",L35<>"Yes"),"Validate evidence",IF(AND(D35="Yes",E35="N/A"),"Status conflict",IF(AND(D35="No",E35<>"N/A"),"Status conflict","OK"))) -> OK
A36: 5. Organizational | B36: 5.35 | C36: Independent review of information security | D36: Yes | E36: Planned | F36: Independent assurance on ISMS design and operation (clause 9.2). First internal audit scheduled before Stage 1. | G36: EV-19 | J36: A-20 | L36: n/a | M36: =IF(AND(E36="Implemented",L36<>"Yes"),"Validate evidence",IF(AND(D36="Yes",E36="N/A"),"Status conflict",IF(AND(D36="No",E36<>"N/A"),"Status conflict","OK"))) -> OK
A37: 5. Organizational | B37: 5.36 | C37: Compliance with policies, rules and standards for information security | D37: Yes | E37: Partial | F37: Checked through AWS Config and MDM compliance reports (R-003, R-004); manager attestation cycle not yet running. | G37: EV-19, EV-23, EV-31 | H37: R-003, R-004 | L37: n/a | M37: =IF(AND(E37="Implemented",L37<>"Yes"),"Validate evidence",IF(AND(D37="Yes",E37="N/A"),"Status conflict",IF(AND(D37="No",E37<>"N/A"),"Status conflict","OK"))) -> OK
A38: 5. Organizational | B38: 5.37 | C38: Documented operating procedures | D38: Yes | E38: Partial | F38: Runbooks for deployment, access, incident and backup held in the wiki (R-003, R-006); ownership and review dates incomplete. | G38: EV-39 | H38: R-003, R-006 | L38: n/a | M38: =IF(AND(E38="Implemented",L38<>"Yes"),"Validate evidence",IF(AND(D38="Yes",E38="N/A"),"Status conflict",IF(AND(D38="No",E38<>"N/A"),"Status conflict","OK"))) -> OK
A39: 6. People | B39: 6.1 | C39: Screening | D39: Yes | E39: Implemented | F39: Background checks proportionate to access to customer data (R-004), within local employment law. | G39: EV-20 | H39: R-004 | L39: Pending | M39: =IF(AND(E39="Implemented",L39<>"Yes"),"Validate evidence",IF(AND(D39="Yes",E39="N/A"),"Status conflict",IF(AND(D39="No",E39<>"N/A"),"Status conflict","OK"))) -> Validate evidence
A40: 6. People | B40: 6.2 | C40: Terms and conditions of employment | D40: Yes | E40: Implemented | F40: Contracts bind staff to security duties, including remote-working obligations (R-004). | G40: EV-20 | H40: R-004 | L40: Pending | M40: =IF(AND(E40="Implemented",L40<>"Yes"),"Validate evidence",IF(AND(D40="Yes",E40="N/A"),"Status conflict",IF(AND(D40="No",E40<>"N/A"),"Status conflict","OK"))) -> Validate evidence
...

Sheet Exclusions
A1: Exclusion Register
A2: Each exclusion passed the five-part test: subject absent, no dependent risk, alternative named, inheritance evidenced, trigger defined.
A4: Ref | B4: Control | C4: Dossier | D4: Reason for exclusion | E4: Alternative or inherited measure | F4: Re-evaluation trigger | G4: Evidence
A5: 7.1 | B5: Physical security perimeters | C5: ED-01 | D5: No company premises; remote-first since founding | E5: 8.1, 7.9; AWS data-centre perimeters via 5.22 | F5: Lease or ownership of any premises | G5: EV-43
A6: 7.2 | B6: Physical entry | C6: ED-01 | D6: No facilities with entry points | E6: 5.15, 5.18, 8.5 (logical access) | F6: Any premises or shared workspace holding company assets | G6: EV-43
A7: 7.3 | B7: Securing offices, rooms and facilities | C7: ED-01 | D7: No offices, rooms or facilities; home offices are not company facilities | E7: 6.7, 7.7, 7.9, 8.1 | F7: Company-controlled office, storage room or lab | G7: EV-43
A8: 7.4 | B8: Physical security monitoring | C8: ED-02 | D8: No premises to monitor; AWS monitors its data centres | E8: 8.15, 8.16; AWS assurance via 5.22 | F8: Loss of AWS assurance evidence or move to non-AWS hosting | G8: EV-12, EV-43
A9: 7.5 | B9: Protecting against physical and environmental threats | C9: ED-02 | D9: No company site; hosting threats inherited from AWS AZ design | E9: 5.29, 5.30, 8.14; AWS assurance via 5.22 | F9: Move to single-AZ or non-AWS hosting; AWS assurance gap | G9: EV-12, EV-43
A10: 7.6 | B10: Working in secure areas | C10: ED-01 | D10: No secure areas exist | E10: 8.2, 8.3 (logical segregation of sensitive work) | F10: Creation of a secure room or lab | G10: EV-43
A11: 7.8 | B11: Equipment siting and protection | C11: ED-03 | D11: No company equipment sited on company premises | E11: 7.9, 8.1; AWS-operated servers | F11: Any on-premises server, network or storage equipment | G11: EV-43
A12: 7.11 | B12: Supporting utilities | C12: ED-02 | D12: No company site with power, cooling or telecoms; AWS provides hosting utilities | E12: 5.30, 8.14; AWS assurance via 5.22 | F12: Any company-operated site or equipment room | G12: EV-12, EV-43
A13: 7.12 | B13: Cabling security | C13: ED-03 | D13: Progress owns no cabling; networks are home ISPs and AWS | E13: 8.24 (encryption in transit), 8.20 | F13: Any company-owned network infrastructure | G13: EV-43
A14: 8.30 | B14: Outsourced development | C14: ED-04 | D14: All development is performed by employees | E14: 8.25, 8.28, 5.19-5.21 as fall-back | F14: Use of any external developer, agency or offshore team | G14: EV-43
A16: Count of exclusions (live): | D16: =COUNTA(A5:A14) -> 10

Sheet Risk Register
A1: Risk Register
A2: R-001 to R-006 from the original brief; R-007 to R-013 are author-proposed and pending ratification by the risk owner. Owners are proposed roles.
A4: Risk ID | B4: Risk description | C4: Likelihood | D4: Impact | E4: Inherent level | F4: Target residual | G4: Treatment | H4: Proposed owner | I4: Source | J4: Applicable controls treating risk (live)
A5: R-001 | B5: Unauthorized access to customer data | C5: Medium | D5: High | E5: High | F5: Medium | G5: Treat | H5: Head of Engineering | I5: Original brief | J5: =COUNTIF(Traceability!E$5:E$97,"●") -> 26
A6: R-002 | B6: Employee laptop theft or loss | C6: Medium | D6: Medium | E6: Medium | F6: Low | G6: Treat | H6: IT Operations Lead | I6: Original brief | J6: =COUNTIF(Traceability!F$5:F$97,"●") -> 13
A7: R-003 | B7: Cloud misconfiguration | C7: High | D7: High | E7: Critical | F7: Medium | G7: Treat (priority) | H7: Cloud Platform Lead | I7: Original brief | J7: =COUNTIF(Traceability!G$5:G$97,"●") -> 23
A8: R-004 | B8: Insider threat | C8: Low | D8: High | E8: Medium | F8: Low | G8: Treat | H8: Head of People | I8: Original brief | J8: =COUNTIF(Traceability!H$5:H$97,"●") -> 24
A9: R-005 | B9: Third-party breach (AWS) | C9: Low | D9: Critical | E9: High | F9: Medium | G9: Treat and share | H9: Head of Engineering | I9: Original brief | J9: =COUNTIF(Traceability!I$5:I$97,"●") -> 10
A10: R-006 | B10: Business continuity failure | C10: Low | D10: High | E10: Medium | F10: Low | G10: Treat | H10: Head of Operations | I10: Original brief | J10: =COUNTIF(Traceability!J$5:J$97,"●") -> 10
A11: R-007 | B11: Phishing or credential theft against remote staff | C11: High | D11: Medium | E11: High | F11: Medium | G11: Treat | H11: IT Operations Lead | I11: Author-proposed | J11: =COUNTIF(Traceability!K$5:K$97,"●") -> 14
A12: R-008 | B12: Ransomware or destructive attack on cloud workloads and backups | C12: Low | D12: Critical | E12: High | F12: Medium | G12: Treat | H12: Cloud Platform Lead | I12: Author-proposed | J12: =COUNTIF(Traceability!L$5:L$97,"●") -> 8
A13: R-009 | B13: Software supply-chain compromise | C13: Medium | D13: High | E13: High | F13: Medium | G13: Treat | H13: Head of Engineering | I13: Author-proposed | J13: =COUNTIF(Traceability!M$5:M$97,"●") -> 10
A14: R-010 | B14: Secrets or credentials exposed in code or pipelines | C14: Medium | D14: High | E14: High | F14: Low | G14: Treat | H14: Head of Engineering | I14: Author-proposed | J14: =COUNTIF(Traceability!N$5:N$97,"●") -> 6
A15: R-011 | B15: Non-compliance with GDPR processor duties or customer contract terms | C15: Medium | D15: High | E15: High | F15: Medium | G15: Treat and share | H15: Data Protection Lead | I15: Author-proposed | J15: =COUNTIF(Traceability!O$5:O$97,"●") -> 13
A16: R-012 | B16: Customer data retained beyond contract or not deleted | C16: Medium | D16: Medium | E16: Medium | F16: Low | G16: Treat | H16: Data Protection Lead | I16: Author-proposed | J16: =COUNTIF(Traceability!P$5:P$97,"●") -> 6
A17: R-013 | B17: API abuse: broken authorization, injection or denial of service | C17: Medium | D17: High | E17: High | F17: Medium | G17: Treat | H17: Head of Engineering | I17: Author-proposed | J17: =COUNTIF(Traceability!Q$5:Q$97,"●") -> 11
A19: Methodology note: the source states qualitative ratings without a scoring matrix. Publish the likelihood and impact criteria and matrix (action A-02) before Stage 1.

Sheet Traceability
A1: Risk-to-Control Traceability Matrix
A2: ● = control treats the risk (Annex A controls only; C-01 to C-03 are on the Additional Controls sheet). Counts are live.
A3: Controls per risk (live) | E3: =COUNTIF(E5:E97,"●") -> 26 | F3: =COUNTIF(F5:F97,"●") -> 13 | G3: =COUNTIF(G5:G97,"●") -> 23 | H3: =COUNTIF(H5:H97,"●") -> 24 | I3: =COUNTIF(I5:I97,"●") -> 10 | J3: =COUNTIF(J5:J97,"●") -> 10 | K3: =COUNTIF(K5:K97,"●") -> 14 | L3: =COUNTIF(L5:L97,"●") -> 8 | ... Q3: =COUNTIF(Q5:Q97,"●") -> 11
A4: Ref | B4: Control | C4: Applicable | D4: Status | E4: R-001 | F4: R-002 | G4: R-003 | H4: R-004 | I4: R-005 | J4: R-006 | K4: R-007 | L4: R-008 | M4: R-009 | N4: R-010 | O4: R-011 | P4: R-012 | Q4: R-013 | R4: Risks treated
A5: 5.1 | B5: Policies for information security | C5: =SoA!D2 -> Yes | D5: =SoA!E2 -> Implemented | E5: ● | G5: ● | R5: =COUNTIF(E5:Q5,"●") -> 2
A6: 5.2 | B6: Information security roles and responsibilities | C6: =SoA!D3 -> Yes | D6: =SoA!E3 -> Implemented | G6: ● | H6: ● | R6: =COUNTIF(E6:Q6,"●") -> 2
A7: 5.3 | B7: Segregation of duties | C7: =SoA!D4 -> Yes | D7: =SoA!E4 -> Partial | E7: ● | G7: ● | H7: ● | R7: =COUNTIF(E7:Q7,"●") -> 3
A8: 5.4 | B8: Management responsibilities | C8: =SoA!D5 -> Yes | D8: =SoA!E5 -> Implemented | H8: ● | K8: ● | R8: =COUNTIF(E8:Q8,"●") -> 2
A9: 5.5 | B9: Contact with authorities | C9: =SoA!D6 -> Yes | D9: =SoA!E6 -> Partial | O9: ● | R9: =COUNTIF(E9:Q9,"●") -> 1
A10: 5.6 | B10: Contact with special interest groups | C10: =SoA!D7 -> Yes | D10: =SoA!E7 -> Partial | K10: ● | R10: =COUNTIF(E10:Q10,"●") -> 1
A11: 5.7 | B11: Threat intelligence | C11: =SoA!D8 -> Yes | D11: =SoA!E8 -> Partial | G11: ● | K11: ● | M11: ● | R11: =COUNTIF(E11:Q11,"●") -> 3
A12: 5.8 | B12: Information security in project management | C12: =SoA!D9 -> Yes | D12: =SoA!E9 -> Partial | G12: ● | Q12: ● | R12: =COUNTIF(E12:Q12,"●") -> 2
A13: 5.9 | B13: Inventory of information and other associated assets | C13: =SoA!D10 -> Yes | D13: =SoA!E10 -> Partial | F13: ● | R13: =COUNTIF(E13:Q13,"●") -> 1
A14: 5.10 | B14: Acceptable use of information and other associated assets | C14: =SoA!D11 -> Yes | D14: =SoA!E11 -> Implemented | F14: ● | H14: ● | K14: ● | R14: =COUNTIF(E14:Q14,"●") -> 3
A15: 5.11 | B15: Return of assets | C15: =SoA!D12 -> Yes | D15: =SoA!E12 -> Implemented | F15: ● | H15: ● | R15: =COUNTIF(E15:Q15,"●") -> 2
A16: 5.12 | B16: Classification of information | C16: =SoA!D13 -> Yes | D16: =SoA!E13 -> Partial | E16: ● | O16: ● | P16: ● | R16: =COUNTIF(E16:Q16,"●") -> 3
A17: 5.13 | B17: Labelling of information | C17: =SoA!D14 -> Yes | D17: =SoA!E14 -> Planned | O17: ● | R17: =COUNTIF(E17:Q17,"●") -> 1
A18: 5.14 | B18: Information transfer | C18: =SoA!D15 -> Yes | D18: =SoA!E15 -> Partial | E18: ● | O18: ● | R18: =COUNTIF(E18:Q18,"●") -> 2
A19: 5.15 | B19: Access control | C19: =SoA!D16 -> Yes | D19: =SoA!E16 -> Implemented | E19: ● | H19: ● | R19: =COUNTIF(E19:Q19,"●") -> 2
A20: 5.16 | B20: Identity management | C20: =SoA!D17 -> Yes | D20: =SoA!E17 -> Implemented | E20: ● | H20: ● | R20: =COUNTIF(E20:Q20,"●") -> 2
A21: 5.17 | B21: Authentication information | C21: =SoA!D18 -> Yes | D21: =SoA!E18 -> Implemented | E21: ● | K21: ● | N21: ● | R21: =COUNTIF(E21:Q21,"●") -> 3
A22: 5.18 | B22: Access rights | C22: =SoA!D19 -> Yes | D22: =SoA!E19 -> Partial | E22: ● | H22: ● | R22: =COUNTIF(E22:Q22,"●") -> 2
A23: 5.19 | B23: Information security in supplier relationships | C23: =SoA!D20 -> Yes | D23: =SoA!E20 -> Partial | I23: ● | M23: ● | R23: =COUNTIF(E23:Q23,"●") -> 2
A24: 5.20 | B24: Addressing information security within supplier agreements | C24: =SoA!D21 -> Yes | D24: =SoA!E21 -> Partial | I24: ● | O24: ● | R24: =COUNTIF(E24:Q24,"●") -> 2
A25: 5.21 | B25: Managing information security in the ICT supply chain | C25: =SoA!D22 -> Yes | D25: =SoA!E22 -> Partial | I25: ● | M25: ● | R25: =COUNTIF(E25:Q25,"●") -> 2
A26: 5.22 | B26: Monitoring, review and change management of supplier services | C26: =SoA!D23 -> Yes | D26: =SoA!E23 -> Partial | I26: ● | R26: =COUNTIF(E26:Q26,"●") -> 1
A27: 5.23 | B27: Information security for use of cloud services | C27: =SoA!D24 -> Yes | D27: =SoA!E24 -> Implemented | G27: ● | I27: ● | R27: =COUNTIF(E27:Q27,"●") -> 2
A28: 5.24 | B28: Information security incident management planning and preparation | C28: =SoA!D25 -> Yes | D28: =SoA!E25 -> Implemented | J28: ● | R28: =COUNTIF(E28:Q28,"●") -> 1
A29: 5.25 | B29: Assessment and decision on information security events | C29: =SoA!D26 -> Yes | D29: =SoA!E26 -> Partial | G29: ● | R29: =COUNTIF(E29:Q29,"●") -> 1
A30: 5.26 | B30: Response to information security incidents | C30: =SoA!D27 -> Yes | D30: =SoA!E27 -> Partial | G30: ● | J30: ● | L30: ● | R30: =COUNTIF(E30:Q30,"●") -> 3
A31: 5.27 | B31: Learning from information security incidents | C31: =SoA!D28 -> Yes | D31: =SoA!E28 -> Partial | J31: ● | R31: =COUNTIF(E31:Q31,"●") -> 1
A32: 5.28 | B32: Collection of evidence | C32: =SoA!D29 -> Yes | D32: =SoA!E29 -> Planned | H32: ● | R32: =COUNTIF(E32:Q32,"●") -> 1
A33: 5.29 | B33: Information security during disruption | C33: =SoA!D30 -> Yes | D33: =SoA!E30 -> Partial | I33: ● | J33: ● | L33: ● | R33: =COUNTIF(E33:Q33,"●") -> 3
A34: 5.30 | B34: ICT readiness for business continuity | C34: =SoA!D31 -> Yes | D34: =SoA!E31 -> Partial | I34: ● | J34: ● | L34: ● | R34: =COUNTIF(E34:Q34,"●") -> 3
A35: 5.31 | B35: Legal, statutory, regulatory and contractual requirements | C35: =SoA!D32 -> Yes | D35: =SoA!E32 -> Implemented | O35: ● | R35: =COUNTIF(E35:Q35,"●") -> 1
A36: 5.32 | B36: Intellectual property rights | C36: =SoA!D33 -> Yes | D36: =SoA!E33 -> Partial | M36: ● | R36: =COUNTIF(E36:Q36,"●") -> 1
A37: 5.33 | B37: Protection of records | C37: =SoA!D34 -> Yes | D37: =SoA!E34 -> Partial | O37: ● | P37: ● | R37: =COUNTIF(E37:Q37,"●") -> 2
A38: 5.34 | B38: Privacy and protection of PII | C38: =SoA!D35 -> Yes | D38: =SoA!E35 -> Partial | O38: ● | P38: ● | R38: =COUNTIF(E38:Q38,"●") -> 2
A39: 5.35 | B39: Independent review of information security | C39: =SoA!D36 -> Yes | D39: =SoA!E36 -> Planned | R39: =COUNTIF(E39:Q39,"●") -> 0
A40: 5.36 | B40: Compliance with policies, rules and standards for information security | C40: =SoA!D37 -> Yes | D40: =SoA!E37 -> Partial | G40: ● | H40: ● | R40: =COUNTIF(E40:Q40,"●") -> 2
...

Sheet Evidence Index
A1: Evidence Reference Index
A2: Owners are proposed roles and systems of record are indicative. 'Controls citing' counts SoA rows that reference the ID.
A4: ID | B4: Evidence artefact | C4: Proposed owner | D4: System of record (indicative) | E4: Cadence | F4: Controls citing (live) | G4: Note
A5: EV-01 | B5: Information security policy, approved by management | C5: ISMS Manager | D5: Policy repository | E5: Annual | F5: =COUNTIF(SoA!$G$2:$G$94,"*"&A5&"*") -> 1
A6: EV-02 | B6: ISMS scope statement and context register (incl. climate-change consideration) | C6: ISMS Manager | D6: Policy repository | E6: Annual | F6: =COUNTIF(SoA!$G$2:$G$94,"*"&A6&"*") -> 0 | G6: Clause 4 evidence
A7: EV-03 | B7: Roles and responsibilities matrix, appointment records | C7: ISMS Manager | D7: Policy repository | E7: On change | F7: =COUNTIF(SoA!$G$2:$G$94,"*"&A7&"*") -> 2
A8: EV-04 | B8: Management review minutes and ISMS KPI pack | C8: Executive sponsor | D8: Document store | E8: Quarterly | F8: =COUNTIF(SoA!$G$2:$G$94,"*"&A8&"*") -> 1
A9: EV-05 | B9: Risk assessment methodology (criteria, matrix) and risk register | C9: Risk Owner | D9: Risk register | E9: Semi-annual | F9: =COUNTIF(SoA!$G$2:$G$94,"*"&A9&"*") -> 0 | G9: Clause 6.1.2 evidence
A10: EV-06 | B10: Risk treatment plan | C10: Risk Owner | D10: Risk register | E10: Semi-annual | F10: =COUNTIF(SoA!$G$2:$G$94,"*"&A10&"*") -> 0 | G10: Clause 6.1.3 evidence
A11: EV-07 | B11: Information asset register with owners and classification | C11: IT Operations Lead | D11: Asset inventory | E11: Quarterly | F11: =COUNTIF(SoA!$G$2:$G$94,"*"&A11&"*") -> 1
A12: EV-08 | B12: Acceptable use policy and signed acknowledgements | C12: Head of People | D12: HR system | E12: Onboarding and annual | F12: =COUNTIF(SoA!$G$2:$G$94,"*"&A12&"*") -> 1
A13: EV-09 | B13: Classification and handling standard; labelling and transfer rules | C13: ISMS Manager | D13: Policy repository | E13: Annual | F13: =COUNTIF(SoA!$G$2:$G$94,"*"&A13&"*") -> 3
A14: EV-10 | B14: Access control policy | C14: Head of Engineering | D14: Policy repository | E14: Annual | F14: =COUNTIF(SoA!$G$2:$G$94,"*"&A14&"*") -> 1
A15: EV-11 | B15: Identity and access configuration exports and quarterly access review records | C15: Cloud Platform Lead | D15: Identity provider, AWS IAM | E15: Quarterly | F15: =COUNTIF(SoA!$G$2:$G$94,"*"&A15&"*") -> 7
A16: EV-12 | B16: Supplier register, due-diligence files and AWS assurance reviews (certificates, SOC reports) | C16: Procurement and ISMS Manager | D16: Supplier register, AWS Artifact | E16: Annual per supplier | F16: =COUNTIF(SoA!$G$2:$G$94,"*"&A16&"*") -> 7
A17: EV-13 | B17: Supplier contracts, DPAs, NDAs and security addenda | C17: Legal | D17: Contract repository | E17: On signature and renewal | F17: =COUNTIF(SoA!$G$2:$G$94,"*"&A17&"*") -> 2
A18: EV-14 | B18: Cloud security standard and shared-responsibility matrix | C18: Cloud Platform Lead | D18: Policy repository | E18: Annual | F18: =COUNTIF(SoA!$G$2:$G$94,"*"&A18&"*") -> 2
A19: EV-15 | B19: Incident response plan, playbooks, incident log, post-incident reviews, tabletop reports | C19: Security Lead | D19: Ticketing system | E19: Per incident; tabletop annually | F19: =COUNTIF(SoA!$G$2:$G$94,"*"&A19&"*") -> 5
A20: EV-16 | B20: Business impact analysis, continuity and DR plans, DR test reports | C20: Head of Operations | D20: Document store | E20: Annual test | F20: =COUNTIF(SoA!$G$2:$G$94,"*"&A20&"*") -> 3
A21: EV-17 | B21: Legal and contractual requirements register | C21: Legal | D21: Document store | E21: Semi-annual | F21: =COUNTIF(SoA!$G$2:$G$94,"*"&A21&"*") -> 1
A22: EV-18 | B22: Record of processing, DPIAs, DSAR procedure and log | C22: Data Protection Lead | D22: Privacy register | E22: Semi-annual | F22: =COUNTIF(SoA!$G$2:$G$94,"*"&A22&"*") -> 1
... A54: EV-50 | B54: Event reporting channel and reporting statistics | C54: Security Lead | D54: Ticketing, chat | E54: Monthly | F54: =COUNTIF(SoA!$G$2:$G$94,"*"&A54&"*") -> 1

Sheet Actions
A1: Priority Remediation Actions
A2: Owners are proposed roles; dates are proposals for management approval. Update Status as work progresses.
A4: ID | B4: Control | C4: Action | D4: Owner | E4: Due | F4: Risk addressed | G4: Status | H4: Days to due (live)
A5: A-01 | B5: Baseline | C5: Confirm whether any staff access company data from personal phones; if so add mobile rule to 8.1 and 6.7 | D5: IT Operations Lead | E5: 46346 | F5: R-002, R-007 | G5: Not started | H5: =E5-DATE(2026,10,26) -> 25
A6: A-02 | B6: Method | C6: Publish risk scoring matrix and likelihood and impact criteria | D6: Risk Owner | E6: 46346 | F6: All | G6: Not started | H6: =E6-DATE(2026,10,26) -> 25
A7: A-03 | B7: ED-01 to ED-04 | C7: Assemble non-applicability dossier (EV-43) including contributor-to-roster reconciliation | D7: ISMS Manager | E7: 46346 | F7: All exclusions | G7: Not started | H7: =E7-DATE(2026,10,26) -> 25
A8: A-04 | B8: 5.22 | C8: Complete and sign off the annual AWS assurance review; schedule reviews for other suppliers | D8: ISMS Manager | E8: 46360 | F8: R-005 | G8: Not started | H8: =E8-DATE(2026,10,26) -> 39
A9: A-05 | B9: 8.34 | C9: Write audit and penetration test protocol with read-only access rules | D9: Security Lead | E9: 46360 | F9: R-001, R-006 | G9: Not started | H9: =E9-DATE(2026,10,26) -> 39
A10: A-06 | B10: 8.23 | C10: Deploy DNS and web filtering to all laptops through MDM | D10: IT Operations Lead | E10: 46367 | F10: R-007 | G10: Not started | H10: =E10-DATE(2026,10,26) -> 46
A11: A-07 | B11: 5.13 | C11: Apply classification tags to cloud data stores and standard document footers | D11: ISMS Manager | E11: 46374 | F11: R-001, R-011 | G11: Not started | H11: =E11-DATE(2026,10,26) -> 53
A12: A-08 | B12: 5.28 | C12: Approve evidence-collection and forensic-readiness procedure; confirm log retention | D12: Security Lead | E12: 46374 | F12: R-001, R-004 | G12: Not started | H12: =E12-DATE(2026,10,26) -> 53
A13: A-09 | B13: 5.18 | C13: Extend quarterly access reviews to all SaaS applications | D13: Cloud Platform Lead | E13: 46374 | F13: R-001, R-004 | G13: Not started | H13: =E13-DATE(2026,10,26) -> 53
A14: A-10 | B14: 8.9 | C14: Enable configuration drift detection and exception process for infrastructure-as-code | D14: Cloud Platform Lead | E14: 46402 | F14: R-003, R-010 | G14: Not started | H14: =E14-DATE(2026,10,26) -> 81
A15: A-11 | B15: 8.16 | C15: Tune alerts and define out-of-hours escalation | D15: Security Lead | E15: 46402 | F15: R-003, R-007 | G15: Not started | H15: =E15-DATE(2026,10,26) -> 81
A16: A-12 | B16: 8.8 | C16: Set remediation SLAs and monthly vulnerability reporting | D16: Security Lead | E16: 46402 | F16: R-003, R-008, R-009 | G16: Not started | H16: =E16-DATE(2026,10,26) -> 81
... A24: A-20 | B24: 5.35 | C24: Complete first independent internal audit of the ISMS | D24: ISMS Manager | E24: 46430 | F24: Clause 9.2 | G24: Not started | H24: =E24-DATE(2026,10,26) -> 109
A26: Days to due is measured from the baseline date 26 Oct 2026 (fixed).

Sheet Additional Controls
A1: Controls Beyond Annex A
A2: Clause 6.1.3 b): controls necessary for a multi-tenant, EU-hosted SaaS provider. They do not change the 93-control count.
A4: Ref | B4: Additional control | C4: Risks | D4: Related Annex A | E4: Status | F4: Evidence Ref
A5: C-01 | B5: Logical tenant isolation for customer data in the multi-tenant platform | C5: R-001 R-013 | D5: 8.3, 8.22, 8.26 | E5: Partial | F5: EV-25, EV-32
A6: C-02 | B6: EU data residency enforcement and sub-processor transparency | C6: R-011 | D6: 5.20, 5.31, 8.9 | E6: Partial | F6: EV-13, EV-37
A7: C-03 | B7: Customer assurance handling: security questionnaires, audit-rights requests, shared-responsibility statement | C7: R-005 R-011 | D7: 5.19, 5.31 | E7: Planned | F7: EV-12, EV-17
